Workbook

Sheet task2
A1: CustomerID | B1: Count | C1: Country | D1: State | E1: City | F1: Zip Code | G1: Lat Long | H1: Latitude | I1: Longitude | J1: Gender | K1: Senior Citizen | L1: Partner | M1: Dependents | N1: Tenure Months | O1: Phone Service | P1: Multiple Lines | Q1: Internet Service | R1: Online Security | S1: Online Backup | T1: Device Protection | U1: Tech Support | V1: Streaming TV | W1: Streaming Movies | X1: Contract | Y1: Paperless Billing | Z1: Payment Method | AA1: Monthly Charges | AB1: Total Charges | AC1: Churn Label | AD1: Churn Value | AE1: Churn Score | AF1: CLTV | AG1: Churn Reason
A2: 3668-QPYBK | B2: 1 | C2: United States | D2: California | E2: Los Angeles | F2: 90003 | G2: 33.964131, -118.272783 | H2: 33.964131 | I2: -118.27278 | J2: Male | K2: No | L2: No | M2: No | N2: 2 | O2: Yes | P2: No | Q2: DSL | R2: Yes | S2: Yes | T2: No | U2: No | V2: No | W2: No | X2: Month-to-month | Y2: Yes | Z2: Mailed check | AA2: 53.85 | AB2: 108.15 | AC2: Yes | AD2: 1 | AE2: 86 | AF2: 3239 | AG2: Competitor made better offer
A3: 9237-HQITU | B3: 1 | C3: United States | D3: California | E3: Los Angeles | F3: 90005 | G3: 34.059281, -118.30742 | H3: 34.059281 | I3: -118.30742 | J3: Female | K3: No | L3: No | M3: Yes | N3: 2 | O3: Yes | P3: No | Q3: Fiber optic | R3: No | S3: No | T3: No | U3: No | V3: No | W3: No | X3: Month-to-month | Y3: Yes | Z3: Electronic check | AA3: 70.7 | AB3: 151.65 | AC3: Yes | AD3: 1 | AE3: 67 | AF3: 2701 | AG3: Moved
A4: 9305-CDSKC | B4: 1 | C4: United States | D4: California | E4: Los Angeles | F4: 90006 | G4: 34.048013, -118.293953 | H4: 34.048013 | I4: -118.29395 | J4: Female | K4: No | L4: No | M4: Yes | N4: 8 | O4: Yes | P4: Yes | Q4: Fiber optic | R4: No | S4: No | T4: Yes | U4: No | V4: Yes | W4: Yes | X4: Month-to-month | Y4: Yes | Z4: Electronic check | AA4: 99.65 | AB4: 820.5 | AC4: Yes | AD4: 1 | AE4: 86 | AF4: 5372 | AG4: Moved
A5: 7892-POOKP | B5: 1 | C5: United States | D5: California | E5: Los Angeles | F5: 90010 | G5: 34.062125, -118.315709 | H5: 34.062125 | I5: -118.31571 | J5: Female | K5: No | L5: Yes | M5: Yes | N5: 28 | O5: Yes | P5: Yes | Q5: Fiber optic | R5: No | S5: No | T5: Yes | U5: Yes | V5: Yes | W5: Yes | X5: Month-to-month | Y5: Yes | Z5: Electronic check | AA5: 104.8 | AB5: 3046.05 | AC5: Yes | AD5: 1 | AE5: 84 | AF5: 5003 | AG5: Moved
A6: 0280-XJGEX | B6: 1 | C6: United States | D6: California | E6: Los Angeles | F6: 90015 | G6: 34.039224, -118.266293 | H6: 34.039224 | I6: -118.26629 | J6: Male | K6: No | L6: No | M6: Yes | N6: 49 | O6: Yes | P6: Yes | Q6: Fiber optic | R6: No | S6: Yes | T6: Yes | U6: No | V6: Yes | W6: Yes | X6: Month-to-month | Y6: Yes | Z6: Bank transfer (automatic) | AA6: 103.7 | AB6: 5036.3 | AC6: Yes | AD6: 1 | AE6: 89 | AF6: 5340 | AG6: Competitor had better devices
A7: 4190-MFLUW | B7: 1 | C7: United States | D7: California | E7: Los Angeles | F7: 90020 | G7: 34.066367, -118.309868 | H7: 34.066367 | I7: -118.30987 | J7: Female | K7: No | L7: Yes | M7: No | N7: 10 | O7: Yes | P7: No | Q7: DSL | R7: No | S7: No | T7: Yes | U7: Yes | V7: No | W7: No | X7: Month-to-month | Y7: No | Z7: Credit card (automatic) | AA7: 55.2 | AB7: 528.35 | AC7: Yes | AD7: 1 | AE7: 78 | AF7: 5925 | AG7: Competitor offered higher download speeds
A8: 8779-QRDMV | B8: 1 | C8: United States | D8: California | E8: Los Angeles | F8: 90022 | G8: 34.02381, -118.156582 | H8: 34.02381 | I8: -118.15658 | J8: Male | K8: Yes | L8: No | M8: No | N8: 1 | O8: No | P8: No phone service | Q8: DSL | R8: No | S8: No | T8: Yes | U8: No | V8: No | W8: Yes | X8: Month-to-month | Y8: Yes | Z8: Electronic check | AA8: 39.65 | AB8: 39.65 | AC8: Yes | AD8: 1 | AE8: 100 | AF8: 5433 | AG8: Competitor offered more data
A9: 1066-JKSGK | B9: 1 | C9: United States | D9: California | E9: Los Angeles | F9: 90024 | G9: 34.066303, -118.435479 | H9: 34.066303 | I9: -118.43548 | J9: Male | K9: No | L9: No | M9: No | N9: 1 | O9: Yes | P9: No | Q9: No | R9: No internet service | S9: No internet service | T9: No internet service | U9: No internet service | V9: No internet service | W9: No internet service | X9: Month-to-month | Y9: No | Z9: Mailed check | AA9: 20.15 | AB9: 20.15 | AC9: Yes | AD9: 1 | AE9: 92 | AF9: 4832 | AG9: Competitor made better offer
A10: 6467-CHFZW | B10: 1 | C10: United States | D10: California | E10: Los Angeles | F10: 90028 | G10: 34.099869, -118.326843 | H10: 34.099869 | I10: -118.32684 | J10: Male | K10: No | L10: Yes | M10: Yes | N10: 47 | O10: Yes | P10: Yes | Q10: Fiber optic | R10: No | S10: Yes | T10: No | U10: No | V10: Yes | W10: Yes | X10: Month-to-month | Y10: Yes | Z10: Electronic check | AA10: 99.35 | AB10: 4749.15 | AC10: Yes | AD10: 1 | AE10: 77 | AF10: 5789 | AG10: Competitor had better devices
A11: 8665-UTDHZ | B11: 1 | C11: United States | D11: California | E11: Los Angeles | F11: 90029 | G11: 34.089953, -118.294824 | H11: 34.089953 | I11: -118.29482 | J11: Male | K11: No | L11: Yes | M11: No | N11: 1 | O11: No | P11: No phone service | Q11: DSL | R11: No | S11: Yes | T11: No | U11: No | V11: No | W11: No | X11: Month-to-month | Y11: No | Z11: Electronic check | AA11: 30.2 | AB11: 30.2 | AC11: Yes | AD11: 1 | AE11: 97 | AF11: 2915 | AG11: Competitor had better devices
A12: 8773-HHUOZ | B12: 1 | C12: United States | D12: California | E12: Los Angeles | F12: 90032 | G12: 34.078821, -118.177576 | H12: 34.078821 | I12: -118.17758 | J12: Female | K12: No | L12: No | M12: No | N12: 17 | O12: Yes | P12: No | Q12: DSL | R12: No | S12: No | T12: No | U12: No | V12: Yes | W12: Yes | X12: Month-to-month | Y12: Yes | Z12: Mailed check | AA12: 64.7 | AB12: 1093.1 | AC12: Yes | AD12: 1 | AE12: 74 | AF12: 3022 | AG12: Competitor offered higher download speeds
A13: 6047-YHPVI | B13: 1 | C13: United States | D13: California | E13: Los Angeles | F13: 90039 | G13: 34.110845, -118.259595 | H13: 34.110845 | I13: -118.2596 | J13: Male | K13: No | L13: No | M13: Yes | N13: 5 | O13: Yes | P13: No | Q13: Fiber optic | R13: No | S13: No | T13: No | U13: No | V13: No | W13: No | X13: Month-to-month | Y13: Yes | Z13: Electronic check | AA13: 69.7 | AB13: 316.9 | AC13: Yes | AD13: 1 | AE13: 66 | AF13: 2454 | AG13: Competitor offered higher download speeds
... A1870: 8361-LTMKD | B1870: 1 | C1870: United States | D1870: California | E1870: Apple Valley | F1870: 92307 | G1870: 34.55082, -117.122396 | H1870: 34.55082 | I1870: -117.1224 | J1870: Male | K1870: Yes | L1870: Yes | M1870: No | N1870: 4 | O1870: Yes | P1870: Yes | Q1870: Fiber optic | R1870: No | S1870: No | T1870: No | U1870: No | V1870: No | W1870: No | X1870: Month-to-month | Y1870: Yes | Z1870: Mailed check | AA1870: 74.4 | AB1870: 306.6 | AC1870: Yes | AD1870: 1 | AE1870: 77 | AF1870: 5839 | AG1870: Competitor offered more data
A1871: 7590-VHVEG | B1871: 1 | C1871: United States | D1871: California | E1871: Los Angeles | F1871: 90001 | G1871: 33.973616, -118.24902 | H1871: 33.973616 | I1871: -118.24902 | J1871: Female | K1871: No | L1871: Yes | M1871: No | N1871: 1 | O1871: No | P1871: No phone service | Q1871: DSL | R1871: No | S1871: Yes | T1871: No | U1871: No | V1871: No | W1871: No | X1871: Month-to-month | Y1871: Yes | Z1871: Electronic check | AA1871: 29.85 | AB1871: 29.85 | AC1871: No | AD1871: 0 | AE1871: 27 | AF1871: 3964
A1872: 5575-GNVDE | B1872: 1 | C1872: United States | D1872: California | E1872: Los Angeles | F1872: 90002 | G1872: 33.949255, -118.246978 | H1872: 33.949255 | I1872: -118.24698 | J1872: Male | K1872: No | L1872: No | M1872: No | N1872: 34 | O1872: Yes | P1872: No | Q1872: DSL | R1872: Yes | S1872: No | T1872: Yes | U1872: No | V1872: No | W1872: No | X1872: One year | Y1872: No | Z1872: Mailed check | AA1872: 56.95 | AB1872: 1889.5 | AC1872: No | AD1872: 0 | AE1872: 61 | AF1872: 3441
A1873: 7795-CFOCW | B1873: 1 | C1873: United States | D1873: California | E1873: Los Angeles | F1873: 90004 | G1873: 34.076259, -118.310715 | H1873: 34.076259 | I1873: -118.31072 | J1873: Male | K1873: No | L1873: No | M1873: No | N1873: 45 | O1873: No | P1873: No phone service | Q1873: DSL | R1873: Yes | S1873: No | T1873: Yes | U1873: Yes | V1873: No | W1873: No | X1873: One year | Y1873: No | Z1873: Bank transfer (automatic) | AA1873: 42.3 | AB1873: 1840.75 | AC1873: No | AD1873: 0 | AE1873: 66 | AF1873: 4307
A1874: 1452-KIOVK | B1874: 1 | C1874: United States | D1874: California | E1874: Los Angeles | F1874: 90007 | G1874: 34.027337, -118.28515 | H1874: 34.027337 | I1874: -118.28515 | J1874: Male | K1874: No | L1874: No | M1874: Yes | N1874: 22 | O1874: Yes | P1874: Yes | Q1874: Fiber optic | R1874: No | S1874: Yes | T1874: No | U1874: No | V1874: Yes | W1874: No | X1874: Month-to-month | Y1874: Yes | Z1874: Credit card (automatic) | AA1874: 89.1 | AB1874: 1949.4 | AC1874: No | AD1874: 0 | AE1874: 43 | AF1874: 4459
A1875: 6713-OKOMC | B1875: 1 | C1875: United States | D1875: California | E1875: Los Angeles | F1875: 90008 | G1875: 34.008293, -118.346766 | H1875: 34.008293 | I1875: -118.34677 | J1875: Female | K1875: No | L1875: No | M1875: No | N1875: 10 | O1875: No | P1875: No phone service | Q1875: DSL | R1875: Yes | S1875: No | T1875: No | U1875: No | V1875: No | W1875: No | X1875: Month-to-month | Y1875: No | Z1875: Mailed check | AA1875: 29.75 | AB1875: 301.9 | AC1875: No | AD1875: 0 | AE1875: 51 | AF1875: 2013
A1876: 6388-TABGU | B1876: 1 | C1876: United States | D1876: California | E1876: Los Angeles | F1876: 90011 | G1876: 34.00709, -118.258681 | H1876: 34.00709 | I1876: -118.25868 | J1876: Male | K1876: No | L1876: No | M1876: No | N1876: 62 | O1876: Yes | P1876: No | Q1876: DSL | R1876: Yes | S1876: Yes | T1876: No | U1876: No | V1876: No | W1876: No | X1876: One year | Y1876: No | Z1876: Bank transfer (automatic) | AA1876: 56.15 | AB1876: 3487.95 | AC1876: No | AD1876: 0 | AE1876: 58 | AF1876: 4529
A1877: 9763-GRSKD | B1877: 1 | C1877: United States | D1877: California | E1877: Los Angeles | F1877: 90012 | G1877: 34.065875, -118.238728 | H1877: 34.065875 | I1877: -118.23873 | J1877: Male | K1877: No | L1877: Yes | M1877: Yes | N1877: 13 | O1877: Yes | P1877: No | Q1877: DSL | R1877: Yes | S1877: No | T1877: No | U1877: No | V1877: No | W1877: No | X1877: Month-to-month | Y1877: Yes | Z1877: Mailed check | AA1877: 49.95 | AB1877: 587.45 | AC1877: No | AD1877: 0 | AE1877: 76 | AF1877: 5764
A1878: 7469-LKBCI | B1878: 1 | C1878: United States | D1878: California | E1878: Los Angeles | F1878: 90013 | G1878: 34.044639, -118.240413 | H1878: 34.044639 | I1878: -118.24041 | J1878: Male | K1878: No | L1878: No | M1878: No | N1878: 16 | O1878: Yes | P1878: No | Q1878: No | R1878: No internet service | S1878: No internet service | T1878: No internet service | U1878: No internet service | V1878: No internet service | W1878: No internet service | X1878: Two year | Y1878: No | Z1878: Credit card (automatic) | AA1878: 18.95 | AB1878: 326.8 | AC1878: No | AD1878: 0 | AE1878: 39 | AF1878: 4726
A1879: 8091-TTVAX | B1879: 1 | C1879: United States | D1879: California | E1879: Los Angeles | F1879: 90014 | G1879: 34.043144, -118.251977 | H1879: 34.043144 | I1879: -118.25198 | J1879: Male | K1879: No | L1879: Yes | M1879: No | N1879: 58 | O1879: Yes | P1879: Yes | Q1879: Fiber optic | R1879: No | S1879: No | T1879: Yes | U1879: No | V1879: Yes | W1879: Yes | X1879: One year | Y1879: No | Z1879: Credit card (automatic) | AA1879: 100.35 | AB1879: 5681.1 | AC1879: No | AD1879: 0 | AE1879: 71 | AF1879: 6432
A1880: 5129-JLPIS | B1880: 1 | C1880: United States | D1880: California | E1880: Los Angeles | F1880: 90016 | G1880: 34.028331, -118.354338 | H1880: 34.028331 | I1880: -118.35434 | J1880: Male | K1880: No | L1880: No | M1880: No | N1880: 25 | O1880: Yes | P1880: No | Q1880: Fiber optic | R1880: Yes | S1880: No | T1880: Yes | U1880: Yes | V1880: Yes | W1880: Yes | X1880: Month-to-month | Y1880: Yes | Z1880: Electronic check | AA1880: 105.5 | AB1880: 2686.05 | AC1880: No | AD1880: 0 | AE1880: 75 | AF1880: 5822
A1881: 3655-SNQYZ | B1881: 1 | C1881: United States | D1881: California | E1881: Los Angeles | F1881: 90017 | G1881: 34.052842, -118.264495 | H1881: 34.052842 | I1881: -118.26449 | J1881: Female | K1881: No | L1881: Yes | M1881: No | N1881: 69 | O1881: Yes | P1881: Yes | Q1881: Fiber optic | R1881: Yes | S1881: Yes | T1881: Yes | U1881: Yes | V1881: Yes | W1881: Yes | X1881: Two year | Y1881: No | Z1881: Credit card (automatic) | AA1881: 113.25 | AB1881: 7895.15 | AC1881: No | AD1881: 0 | AE1881: 43 | AF1881: 5141
A1882: 8191-XWSZG | B1882: 1 | C1882: United States | D1882: California | E1882: Los Angeles | F1882: 90018 | G1882: 34.028735, -118.317236 | H1882: 34.028735 | I1882: -118.31724 | J1882: Female | K1882: No | L1882: No | M1882: No | N1882: 52 | O1882: Yes | P1882: No | Q1882: No | R1882: No internet service | S1882: No internet service | T1882: No internet service | U1882: No internet service | V1882: No internet service | W1882: No internet service | X1882: One year | Y1882: No | Z1882: Mailed check | AA1882: 20.65 | AB1882: 1022.95 | AC1882: No | AD1882: 0 | AE1882: 35 | AF1882: 5186
... A2235: 3649-JPUGY | B2235: 1 | C2235: United States | D2235: California | E2235: San Bernardino | F2235: 92407 | G2235: 34.250069, -117.393949 | H2235: 34.250069 | I2235: -117.39395 | J2235: Male | K2235: No | L2235: No | M2235: No | N2235: 72 | O2235: Yes | P2235: Yes | Q2235: DSL | R2235: No | S2235: Yes | T2235: Yes | U2235: Yes | V2235: Yes | W2235: Yes | X2235: Two year | Y2235: Yes | Z2235: Bank transfer (automatic) | AA2235: 88.6 | AB2235: 6201.95 | AC2235: No | AD2235: 0 | AE2235: 52 | AF2235: 5842
A2236: 4472-LVYGI | B2236: 1 | C2236: United States | D2236: California | E2236: San Bernardino | F2236: 92408 | G2236: 34.084909, -117.258107 | H2236: 34.084909 | I2236: -117.25811 | J2236: Female | K2236: No | L2236: Yes | M2236: No | N2236: 0 | O2236: No | P2236: No phone service | Q2236: DSL | R2236: Yes | S2236: No | T2236: Yes | U2236: Yes | V2236: Yes | W2236: No | X2236: Two year | Y2236: Yes | Z2236: Bank transfer (automatic) | AA2236: 52.55 | AC2236: No | AD2236: 0 | AE2236: 36 | AF2236: 2578
A2237: 3552-CTCYF | B2237: 1 | C2237: United States | D2237: California | E2237: San Bernardino | F2237: 92411 | G2237: 34.122501, -117.320138 | H2237: 34.122501 | I2237: -117.32014 | J2237: Male | K2237: No | L2237: Yes | M2237: Yes | N2237: 63 | O2237: Yes | P2237: Yes | Q2237: Fiber optic | R2237: No | S2237: Yes | T2237: Yes | U2237: No | V2237: Yes | W2237: Yes | X2237: Two year | Y2237: Yes | Z2237: Bank transfer (automatic) | AA2237: 104.8 | AB2237: 6597.25 | AC2237: No | AD2237: 0 | AE2237: 20 | AF2237: 4046
A2238: 6778-YSNIH | B2238: 1 | C2238: United States | D2238: California | E2238: Riverside | F2238: 92501 | G2238: 33.994676, -117.372498 | H2238: 33.994676 | I2238: -117.3725 | J2238: Female | K2238: No | L2238: No | M2238: No | N2238: 2 | O2238: Yes | P2238: No | Q2238: DSL | R2238: No | S2238: Yes | T2238: No | U2238: No | V2238: Yes | W2238: No | X2238: Month-to-month | Y2238: Yes | Z2238: Electronic check | AA2238: 59 | AB2238: 114.15 | AC2238: No | AD2238: 0 | AE2238: 33 | AF2238: 5810
A2239: 5756-OZRIO | B2239: 1 | C2239: United States | D2239: California | E2239: Riverside | F2239: 92504 | G2239: 33.9108, -117.398153 | H2239: 33.9108 | I2239: -117.39815 | J2239: Male | K2239: Yes | L2239: Yes | M2239: No | N2239: 61 | O2239: Yes | P2239: Yes | Q2239: DSL | R2239: No | S2239: Yes | T2239: No | U2239: No | V2239: No | W2239: Yes | X2239: One year | Y2239: No | Z2239: Bank transfer (automatic) | AA2239: 64.05 | AB2239: 3902.6 | AC2239: No | AD2239: 0 | AE2239: 29 | AF2239: 4001
A2240: 6579-JPICP | B2240: 1 | C2240: United States | D2240: California | E2240: Riverside | F2240: 92505 | G2240: 33.920907, -117.489426 | H2240: 33.920907 | I2240: -117.48943 | J2240: Male | K2240: No | L2240: No | M2240: No | N2240: 1 | O2240: Yes | P2240: No | Q2240: No | R2240: No internet service | S2240: No internet service | T2240: No internet service | U2240: No internet service | V2240: No internet service | W2240: No internet service | X2240: Month-to-month | Y2240: No | Z2240: Mailed check | AA2240: 20.4 | AB2240: 20.4 | AC2240: No | AD2240: 0 | AE2240: 46 | AF2240: 2968
A2241: 4134-BSXLX | B2241: 1 | C2241: United States | D2241: California | E2241: Riverside | F2241: 92507 | G2241: 33.976328, -117.319786 | H2241: 33.976328 | I2241: -117.31979 | J2241: Male | K2241: No | L2241: Yes | M2241: No | N2241: 28 | O2241: Yes | P2241: No | Q2241: DSL | R2241: Yes | S2241: Yes | T2241: No | U2241: Yes | V2241: No | W2241: No | X2241: Month-to-month | Y2241: No | Z2241: Mailed check | AA2241: 60.9 | AB2241: 1785.65 | AC2241: No | AD2241: 0 | AE2241: 76 | AF2241: 3851
A2242: 0505-SPOOW | B2242: 1 | C2242: United States | D2242: California | E2242: Riverside | F2242: 92508 | G2242: 33.885499, -117.324959 | H2242: 33.885499 | I2242: -117.32496 | J2242: Female | K2242: No | L2242: Yes | M2242: No | N2242: 70 | O2242: Yes | P2242: No | Q2242: No | R2242: No internet service | S2242: No internet service | T2242: No internet service | U2242: No internet service | V2242: No internet service | W2242: No internet service | X2242: Two year | Y2242: No | Z2242: Bank transfer (automatic) | AA2242: 19.8 | AB2242: 1397.65 | AC2242: No | AD2242: 0 | AE2242: 30 | AF2242: 4500
A2243: 4374-YMUSQ | B2243: 1 | C2243: United States | D2243: California | E2243: Lake Elsinore | F2243: 92530 | G2243: 33.655421, -117.391751 | H2243: 33.655421 | I2243: -117.39175 | J2243: Male | K2243: No | L2243: No | M2243: No | N2243: 34 | O2243: Yes | P2243: Yes | Q2243: Fiber optic | R2243: Yes | S2243: Yes | T2243: Yes | U2243: Yes | V2243: Yes | W2243: Yes | X2243: One year | Y2243: No | Z2243: Credit card (automatic) | AA2243: 116.25 | AB2243: 3899.05 | AC2243: No | AD2243: 0 | AE2243: 22 | AF2243: 4022
A2244: 4513-CXYIX | B2244: 1 | C2244: United States | D2244: California | E2244: Lake Elsinore | F2244: 92532 | G2244: 33.705836, -117.318204 | H2244: 33.705836 | I2244: -117.3182 | J2244: Female | K2244: Yes | L2244: Yes | M2244: No | N2244: 71 | O2244: Yes | P2244: Yes | Q2244: Fiber optic | R2244: Yes | S2244: No | T2244: No | U2244: No | V2244: No | W2244: No | X2244: Two year | Y2244: Yes | Z2244: Credit card (automatic) | AA2244: 80.7 | AB2244: 5676 | AC2244: No | AD2244: 0 | AE2244: 54 | AF2244: 4583
A2245: 3957-HHLMR | B2245: 1 | C2245: United States | D2245: California | E2245: Aguanga | F2245: 92536 | G2245: 33.482243, -116.827173 | H2245: 33.482243 | I2245: -116.82717 | J2245: Female | K2245: No | L2245: Yes | M2245: No | N2245: 70 | O2245: Yes | P2245: Yes | Q2245: DSL | R2245: Yes | S2245: No | T2245: No | U2245: No | V2245: No | W2245: Yes | X2245: One year | Y2245: No | Z2245: Bank transfer (automatic) | AA2245: 65.2 | AB2245: 4543.15 | AC2245: No | AD2245: 0 | AE2245: 20 | AF2245: 6316
A2246: 7803-XOCCZ | B2246: 1 | C2246: United States | D2246: California | E2246: Anza | F2246: 92539 | G2246: 33.527605, -116.666551 | H2246: 33.527605 | I2246: -116.66655 | J2246: Female | K2246: No | L2246: Yes | M2246: Yes | N2246: 52 | O2246: Yes | P2246: No | Q2246: Fiber optic | R2246: Yes | S2246: No | T2246: Yes | U2246: Yes | V2246: No | W2246: No | X2246: Month-to-month | Y2246: Yes | Z2246: Bank transfer (automatic) | AA2246: 84.05 | AB2246: 4326.8 | AC2246: No | AD2246: 0 | AE2246: 48 | AF2246: 6099
A2247: 5736-YEJAX | B2247: 1 | C2247: United States | D2247: California | E2247: Hemet | F2247: 92543 | G2247: 33.739415, -116.968339 | H2247: 33.739415 | I2247: -116.96834 | J2247: Male | K2247: No | L2247: No | M2247: No | N2247: 69 | O2247: Yes | P2247: Yes | Q2247: DSL | R2247: Yes | S2247: Yes | T2247: Yes | U2247: Yes | V2247: Yes | W2247: No | X2247: Two year | Y2247: Yes | Z2247: Credit card (automatic) | AA2247: 79.45 | AB2247: 5502.55 | AC2247: No | AD2247: 0 | AE2247: 28 | AF2247: 5189
A2248: 8981-FJGLA | B2248: 1 | C2248: United States | D2248: California | E2248: Hemet | F2248: 92545 | G2248: 33.734933, -117.044145 | H2248: 33.734933 | I2248: -117.04415 | J2248: Male | K2248: No | L2248: No | M2248: Yes | N2248: 11 | O2248: Yes | P2248: Yes | Q2248: Fiber optic | R2248: No | S2248: No | T2248: Yes | U2248: No | V2248: No | W2248: No | X2248: Month-to-month | Y2248: Yes | Z2248: Mailed check | AA2248: 78 | AB2248: 851.8 | AC2248: No | AD2248: 0 | AE2248: 23 | AF2248: 4886
...

Sheet Sheet2
A1: Metric | B1: Value | E1: Internet Service | F1: Churned Customers
A2: Total Customers | B2: =COUNTA(task2!A3:A7038) -> 7036 | E2: DSL | F2: =COUNTIFS(task2!Q3:Q7038,"DSL",task2!AC3:AC7038,"YES") -> 458
A3: Churned Customers | B3: =COUNTIF(task2!AC3:AC7038,"Yes") -> 1868 | E3: Fiber optic | F3: =COUNTIFS(task2!Q3:Q7038,"FIBER OPTIC",task2!AC3:AC7038,"YES") -> 1297
A4: Stayed Customers | B4: =COUNTIF(task2!AC3:AC7038,"No") -> 5168 | E4: No | F4: =COUNTIFS(task2!Q3:Q7038,"NO",task2!AC3:AC7038,"YES") -> 113
A5: Churn Rate | B5: =2015/7036 -> 0.28638431
A8: Contract | B8: Churned Customers | E8: Engagement Service | F8: Churned Customers
A9: Month-to-month | B9: =COUNTIFS(task2!X3:X7038,"MONTH-TO-MONTH",task2!AC3:AC7038,"YES") -> 1654 | E9: Tech Support – Yes | F9: =COUNTIFS(task2!U:U,"Yes",task2!AC:AC,"Yes") -> 310
A10: One year | B10: =COUNTIFS(task2!X3:X7038,"ONE YEAR",task2!AC3:AC7038,"YES") -> 166 | E10: Tech Support – No | F10: =COUNTIFS(task2!U:U,"NO",task2!AC:AC,"Yes") -> 1446
A11: Two year | B11: =COUNTIFS(task2!X3:X7038,"TWO YEAR",task2!AC3:AC7038,"YES") -> 48 | E11: Online Security – Yes | F11: =COUNTIFS(task2!R:R,"Yes",task2!AC:AC,"Yes") -> 295
E12: Online Security – No | F12: =COUNTIFS(task2!R:R,"NO",task2!AC:AC,"Yes") -> 1461
A13: Tenure Group | B13: Churned Customers | E13: Online Backup – Yes | F13: =COUNTIFS(task2!S:S,"Yes",task2!AC:AC,"Yes") -> 523
A14: 0–12 Months | B14: =COUNTIFS(task2!N3:N7038,">=0",task2!N3:N7038,"<=12",task2!AC3:AC7038,"YES") -> 1036 | E14: Online Backup – No | F14: =COUNTIFS(task2!S:S,"NO",task2!AC:AC,"Yes") -> 1233
A15: 13–24 Months | B15: =COUNTIFS(task2!N3:N7038,">=13",task2!N3:N7038,"<=24",task2!AC3:AC7038,"YES") -> 294
A16: 25–48 Months | B16: =COUNTIFS(task2!N3:N7038,">=25",task2!N3:N7038,"<=48",task2!AC3:AC7038,"YES") -> 325
A17: 49+ Months | B17: =COUNTIFS(task2!N3:N7038,">=49",task2!AC3:AC7038,"YES") -> 213
A19: Monthly Charges | B19: Churned Customers
A20: Below $50 | B20: =COUNTIFS(task2!AA3:AA7038,"<50",task2!AC3:AC7038,"Yes") -> 361
A21: $50–$100 | B21: =COUNTIFS(task2!AA3:AA7038,">=50",task2!AA3:AA7038,"<=100",task2!AC3:AC7038,"Yes") -> 1254
A22: Above $100 | B22: =COUNTIFS(task2!AA3:AA7038,">50",task2!AC3:AC7038,"Yes") -> 1507
